Workbook

Sheet FNOMO_CURRENT_PROGRESS
A1: FNOMO CURRENT PROGRESS
A2: Live snapshot from FNOMO_MASTER_PIPELINE after WhatsApp lead separation
A4: Metric | B4: Value | C4: Operator Meaning | D4: Next Control
A5: Total pipeline leads | B5: 185 | C5: Live pipeline health signal | D5: Keep next action current
A6: Contacted leads | B6: 99 | C6: Live pipeline health signal | D6: Keep next action current
A7: New leads | B7: 86 | C7: Live pipeline health signal | D7: Keep next action current
A8: Tier A total | B8: 49 | C8: Live pipeline health signal | D8: Keep next action current
A9: Tier A contacted | B9: 28 | C9: Live pipeline health signal | D9: Keep next action current
A10: Tier A still new | B10: 21 | C10: Highest priority drift risk | D10: Clear before Tier B work
A11: Active leads | B11: 120 | C11: Live pipeline health signal | D11: Keep next action current
A12: Waiting leads | B12: 65 | C12: Live pipeline health signal | D12: Keep next action current
A13: Contacted today | B13: 47 | C13: Live pipeline health signal | D13: Keep next action current
A14: Follow-ups due 2026-05-03 | B14: 111 | C14: Follow-up queue pressure | D14: Prepare WhatsApp/email follow-up blocks
A15: Follow-ups due 2026-05-04 | B15: 53 | C15: Follow-up queue pressure | D15: Prepare WhatsApp/email follow-up blocks
A16: WhatsApp batch rows | B16: 20 | C16: Separate raw lead batch mirrored into pipeline | D16: Use WHATSAPP_CA_LEADS for source details
A18: Stage | B18: Count
A19: Contacted | B19: 99
A20: New | B20: 86
A22: Tier | B22: Count
A23: A | B23: 49
A24: B | B24: 135
A25: C | B25: 1
A27: Immediate Operator Note
A28: Dashboard was stale because it was connected to GTM_Schedule/Outreach_Database. This sheet now shows live FNOMO_MASTER_PIPELINE progress. Tier A still-new count is 21.

Sheet Outreach_Database
A1: ID | B1: Status | C1: Outreach Date | D1: Members Joined | E1: Group Name | F1: Focus Area | G1: Outreach Script | H1: Link | I1: Platform | J1: Question Asked | K1: Your Response | L1: User Reaction | M1: Follow-up | N1: Decision Quality | O1: Admin Handle (@) | P1: Decision Proximity (1-10) | Q1: The Hook (Entry Angle) | R1: Influence Score (1-5)
A2: 1 | B2: ⚪ New | D2: 0 | E2: r/IndiaInvestments | F2: Core Wealth Validation | G2: Your group is discussing trades daily. We've built a decision layer to help members validate actions... | H2: https://www.reddit.com/r/IndiaInvestments/ | I2: Reddit
A3: 2 | B3: ⚪ New | D3: 0 | E3: r/IndianStreetBets | F3: Speculative Trade Validation | G3: Your group is discussing trades daily. We've built a decision layer to help members validate actions... | H3: https://www.reddit.com/r/IndianStreetBets/ | I3: Reddit
A4: 3 | B4: ⚪ New | D4: 0 | E4: r/PersonalFinanceIndia | F4: Long-term Planning | G4: Your group is discussing trades daily. We've built a decision layer to help members validate actions... | H4: https://www.reddit.com/r/personalfinanceindia/ | I4: Reddit
A5: 4 | B5: ⚪ New | D5: 0 | E5: r/Indiantradingbets | F5: Trade Setup Confirmation | G5: Your group is discussing trades daily. We've built a decision layer to help members validate actions... | H5: https://www.reddit.com/r/Indiantradingbets/ | I5: Reddit
A6: 5 | B6: ⚪ New | D6: 0 | E6: r/dalalstreetbets | F6: Speculative Discussions | G6: Your group is discussing trades daily. We've built a decision layer to help members validate actions... | H6: https://www.reddit.com/r/dalalstreetbets/ | I6: Reddit
A7: 6 | B7: ⚪ New | D7: 0 | E7: r/StockMarketIndia | F7: General Stock Validation | G7: Your group is discussing trades daily. We've built a decision layer to help members validate actions... | H7: https://www.reddit.com/r/StockMarketIndia/ | I7: Reddit
A8: 7 | B8: ⚪ New | D8: 0 | E8: r/FIREIndia | F8: Early Retirement Logic | G8: Your group is discussing trades daily. We've built a decision layer to help members validate actions... | H8: https://www.reddit.com/r/FIREIndia/ | I8: Reddit
A9: 8 | B9: ⚪ New | D9: 0 | E9: r/IndiaTax | F9: High-Impact Tax Decisions | G9: Your group is discussing trades daily. We've built a decision layer to help members validate actions... | H9: https://www.reddit.com/r/IndiaTax/ | I9: Reddit
A10: 9 | B10: ⚪ New | D10: 0 | E10: r/IndiaCreditCards | F10: Reward/Purchase Decisions | G10: Your group is discussing trades daily. We've built a decision layer to help members validate actions... | H10: https://www.google.com/search?q=https://www.reddit.com/r/IndiaCreditCards/ | I10: Reddit
A11: 10 | B11: ⚪ New | D11: 0 | E11: r/StartupIndia | F11: Founders' Financial Planning | G11: Your group is discussing trades daily. We've built a decision layer to help members validate actions... | H11: https://www.reddit.com/r/StartupIndia/ | I11: Reddit
A12: 11 | B12: ⚪ New | D12: 0 | E12: r/MutualFundsIndia | F12: Product Comparison | G12: Your group is discussing trades daily. We've built a decision layer to help members validate actions... | H12: https://www.reddit.com/r/MutualFundsIndia/ | I12: Reddit
A13: 12 | B13: ⚪ New | D13: 0 | E13: r/IndiaMarket | F13: Macro Market Analysis | G13: Your group is discussing trades daily. We've built a decision layer to help members validate actions... | H13: https://www.google.com/search?q=https://www.reddit.com/r/IndiaMarket/ | I13: Reddit
... A101: 100 | B101: ⚪ New | D101: 0 | E101: Stock Market Daily Analysis | F101: Pre-Market Routine Wedge | G101: Your group is discussing trades daily. We've built a decision layer to help members validate actions... | H101: https://www.google.com/search?q=https://t.me/dailyanalysisindia | I101: Telegram
A102: 101 | B102: ⚪ New | D102: 0 | E102: Sample Telegram Group | F102: Sample Focus | I102: Telegram | J102: Should I buy HDFC? | K102: Structured (Score, Risk, Reason, Alternative) | L102: Asked More | N102: 7
A103: 102 | B103: 🔥 Priority 1 | E103: The Safe Trader Academy | O103: @AnkitThakur / 9297506666 | P103: 10 | Q103: Leveraging Fnomo...
A104: 103 | B104: ? New | E104: Dr. Skand Kumar Trivedi | F104: Doctors | I104: Doctors | J104: Last wrong investment/financial decision? What was the decision process? | Q104: Decision validation before investment action
A105: 104 | B105: ? New | E105: Dr. Rajnees h Kachha ra | F105: Doctors | I105: Doctors | J105: Last wrong investment/financial decision? What was the decision process? | Q105: Decision validation before investment action
A106: 105 | B106: ? New | E106: Dr. Vinit Pandey | F106: Doctors | I106: Doctors | J106: Last wrong investment/financial decision? What was the decision process? | Q106: Decision validation before investment action
A107: 106 | B107: ? New | E107: Dr. Aaditya Sirohi | F107: Doctors | I107: Doctors | J107: Last wrong investment/financial decision? What was the decision process? | Q107: Decision validation before investment action
A108: 107 | B108: ? New | E108: Dr. Gopal Batni | F108: Doctors | I108: Doctors | J108: Last wrong investment/financial decision? What was the decision process? | Q108: Decision validation before investment action
A109: 108 | B109: ? New | E109: Dr. Neeraj Jain | F109: Doctors | I109: Doctors | J109: Last wrong investment/financial decision? What was the decision process? | Q109: Decision validation before investment action
A110: 109 | B110: ? New | E110: Dr. Amit Joshi | F110: Doctors | I110: Doctors | J110: Last wrong investment/financial decision? What was the decision process? | Q110: Decision validation before investment action
A111: 110 | B111: ? New | E111: Dr. Seetha Lekshm i B | F111: Doctors | I111: Doctors | J111: Last wrong investment/financial decision? What was the decision process? | Q111: Decision validation before investment action
A112: 111 | B112: ? New | E112: Dr. Rohit Joshi | F112: Doctors | I112: Doctors | J112: Last wrong investment/financial decision? What was the decision process? | Q112: Decision validation before investment action
A113: 112 | B113: ? New | E113: Dr. Vikram Balwani | F113: Doctors | I113: Doctors | J113: Last wrong investment/financial decision? What was the decision process? | Q113: Decision validation before investment action
A114: 113 | B114: ? New | E114: Dr. Santos h Choudh ary | F114: Doctors | I114: Doctors | J114: Last wrong investment/financial decision? What was the decision process? | Q114: Decision validation before investment action
A115: 114 | B115: ? New | E115: Dr. Arpit Tiwari | F115: Doctors | I115: Doctors | J115: Last wrong investment/financial decision? What was the decision process? | Q115: Decision validation before investment action
... A163: 162 | B163: ? New | E163: Shri Ram Global School | F163: Schools | I163: Schools | J163: Do students act on confidence before validating judgment? | Q163: Decision validation as a student/parent capability

Sheet GTM_Schedule
B2: FNOMO TODO EXECUTION CONTROL SHEET
B3: Update Task Status and Owner only. Dashboard refreshes automatically for Kush and Indu.
B4: Day | C4: Phase | D4: Quest Title | E4: Primary Objective | F4: Success Metric | G4: Task Status | H4: Owner | I4: Priority | J4: Progress
B5: Day 1 | C5: Phase 1 | Association and high-value lead buildout | D5: Contact Doctor Associations | E5: Outreach to doctor associations | F5: Priority contacts identified, first outreach sent, next follow-up date logged | G5: Not Started | H5: Kush | I5: Medium | J5: =IF(G5="Done",1,IF(G5="In Progress",0.6,IF(G5="Waiting",0.35,IF(G5="Blocked",0.15,0))))
B6: Day 2 | C6: Phase 1 | Association and high-value lead buildout | D6: Contact Business Associations | E6: Outreach to business associations | F6: Priority contacts identified, first outreach sent, next follow-up date logged | G6: Not Started | H6: Kush | I6: Medium | J6: =IF(G6="Done",1,IF(G6="In Progress",0.6,IF(G6="Waiting",0.35,IF(G6="Blocked",0.15,0))))
B7: Day 3 | C7: Phase 1 | Association and high-value lead buildout | D7: Contact CA Associations | E7: Outreach to CA associations | F7: Priority contacts identified, first outreach sent, next follow-up date logged | G7: In Progress | H7: Kush | I7: Medium | J7: =IF(G7="Done",1,IF(G7="In Progress",0.6,IF(G7="Waiting",0.35,IF(G7="Blocked",0.15,0))))
B8: Day 4 | C8: Phase 1 | Association and high-value lead buildout | D8: Identify Business Owners >2Cr | E8: Find and reach high value business owners | F8: Qualified target list built with owners, contacts, and next actions | G8: Not Started | H8: Kush | I8: High | J8: =IF(G8="Done",1,IF(G8="In Progress",0.6,IF(G8="Waiting",0.35,IF(G8="Blocked",0.15,0))))
B9: Day 5 | C9: Phase 2 | Platform and channel partnerships | D9: Reach out Practo | E9: Platform partnership outreach | F9: Decision-maker identified, personalized outreach sent, reply tracked | G9: In Progress | H9: Kush | I9: High | J9: =IF(G9="Done",1,IF(G9="In Progress",0.6,IF(G9="Waiting",0.35,IF(G9="Blocked",0.15,0))))
B10: Day 6 | C10: Phase 2 | Platform and channel partnerships | D10: Reach out Blinkit | E10: Platform partnership outreach | F10: Decision-maker identified, personalized outreach sent, reply tracked | G10: In Progress | H10: Kush | I10: High | J10: =IF(G10="Done",1,IF(G10="In Progress",0.6,IF(G10="Waiting",0.35,IF(G10="Blocked",0.15,0))))
B11: Day 7 | C11: Phase 2 | Platform and channel partnerships | D11: Reach out Zomato | E11: Platform partnership outreach | F11: Decision-maker identified, personalized outreach sent, reply tracked | G11: In Progress | H11: Kush | I11: High | J11: =IF(G11="Done",1,IF(G11="In Progress",0.6,IF(G11="Waiting",0.35,IF(G11="Blocked",0.15,0))))
B12: Day 8 | C12: Phase 2 | Platform and channel partnerships | D12: Reach out Swiggy | E12: Platform partnership outreach | F12: Decision-maker identified, personalized outreach sent, reply tracked | G12: In Progress | H12: Kush | I12: High | J12: =IF(G12="Done",1,IF(G12="In Progress",0.6,IF(G12="Waiting",0.35,IF(G12="Blocked",0.15,0))))
B13: Day 9 | C13: Phase 2 | Platform and channel partnerships | D13: Reach out MyGate | E13: Platform partnership outreach | F13: Decision-maker identified, personalized outreach sent, reply tracked | G13: In Progress | H13: Kush | I13: Medium | J13: =IF(G13="Done",1,IF(G13="In Progress",0.6,IF(G13="Waiting",0.35,IF(G13="Blocked",0.15,0))))
B14: Day 10 | C14: Phase 2 | Platform and channel partnerships | D14: Explore National Platforms | E14: Find expansion platforms | F14: New target set shortlisted and first 5 next moves defined | G14: In Progress | H14: Kush | I14: Low | J14: =IF(G14="Done",1,IF(G14="In Progress",0.6,IF(G14="Waiting",0.35,IF(G14="Blocked",0.15,0))))
B15: Day 11 | C15: Phase 2 | Platform and channel partnerships | D15: Explore Event Platforms | E15: Find event-based growth channels | F15: New target set shortlisted and first 5 next moves defined | G15: Not Started | H15: Kush | I15: Low | J15: =IF(G15="Done",1,IF(G15="In Progress",0.6,IF(G15="Waiting",0.35,IF(G15="Blocked",0.15,0))))
B16: Day 12 | C16: Phase 2 | Platform and channel partnerships | D16: Restaurant Partnerships | E16: Tie up with restaurants | F16: Clear deliverable completed and next step logged | G16: Not Started | H16: Kush | I16: Medium | J16: =IF(G16="Done",1,IF(G16="In Progress",0.6,IF(G16="Waiting",0.35,IF(G16="Blocked",0.15,0))))
... B40: Day 36 | C40: Phase 6 | Demand generation and trust building | D40: Free Investing Sessions | E40: General sessions | F40: Campaign plan finalized with target audience, owner, and first launch date | G40: Not Started | H40: Kush | I40: Medium | J40: =IF(G40="Done",1,IF(G40="In Progress",0.6,IF(G40="Waiting",0.35,IF(G40="Blocked",0.15,0))))

Sheet Calc_Engine
B2: Calculation Engine
B4: KPI | C4: Value | D4: Status | E4: Count | G4: Date | H4: Volume | I4: Conversions
B5: Total Outreach Volume | C5: =COUNTA(OutreachData[ID]) | D5: New | E5: =COUNTIF(OutreachData[Status], D5) | G5: =IFERROR(__xludf.DUMMYFUNCTION("SORT(UNIQUE(FILTER(OutreachData[Outreach Date], OutreachData[Outreach Date]<>"""")))"),"#N/A") | H5: {=IF(G5:G1003="", "", COUNTIFS(OutreachData[Outreach Date], G5:G1003))} | I5: {=IF(G5:G1003="", "", COUNTIFS(OutreachData[Outreach Date], G5:G1003, OutreachData[Status], "Done"))}
B6: Pending Responses | C6: =COUNTIF(OutreachData[Status], "Follow-up") + COUNTIF(OutreachData[Status], "Pitching") | D6: Pitching | E6: =COUNTIF(OutreachData[Status], D6)
B7: Total Members Joined | C7: =SUM(OutreachData[Members Joined]) | D7: Follow-up | E7: =COUNTIF(OutreachData[Status], D7)
B8: Conversion Rate | C8: =COUNTIF(OutreachData[Status], "Done") / C5 | D8: Done | E8: =COUNTIF(OutreachData[Status], D8)

Sheet Dashboard
X1: Status Options | Y1: Owner Options | Z1: Priority Options
B2: FNOMO LIVE PIPELINE DASHBOARD | X2: Not Started | Y2: Kush | Z2: High
B3: Connected to FNOMO_MASTER_PIPELINE + WHATSAPP_CA_LEADS. Current progress refreshed by Codex on 2026-05-02. | X3: In Progress | Y3: Indu | Z3: Medium
B4: Total Leads | F4: Contacted | J4: Tier A Pending | N4: Follow-ups Due May 4 | X4: Waiting | Y4: Codex | Z4: Low
B5: 185 | F5: 99 | J5: 21 | N5: 53 | X5: Blocked | Y5: Shared
X6: Done
B9: New | F9: Active | J9: Waiting | N9: Contacted Today
B10: 86 | F10: 120 | J10: 65 | N10: 47
B14: Status Overview | H14: Phase Performance | N14: Owner Accountability
B15: Status | C15: Count | D15: Share | E15: Target Signal | F15: Health | H15: Phase | I15: Open | J15: Done | K15: Completion % | L15: Reading | N15: Owner | O15: Open | P15: Done | Q15: Share of Open | R15: Reading
B16: Not Started | C16: =COUNTIF(GTM_Schedule!$G$5:$G$40,B16) | D16: =IFERROR(C16/COUNTA(GTM_Schedule!$D$5:$D$40),0) | E16: Watch | F16: =REPT("|",ROUND(D16*20,0)) | H16: Phase 1 | I16: =COUNTIF(GTM_Schedule!$C$5:$C$40,"Phase 1*")-COUNTIFS(GTM_Schedule!$C$5:$C$40,"Phase 1*",GTM_Schedule!$G$5:$G$40,"Done") | J16: =COUNTIFS(GTM_Schedule!$C$5:$C$40,"Phase 1*",GTM_Schedule!$G$5:$G$40,"Done") | K16: =IFERROR(J16/(I16+J16),0) | L16: =IF(K16>=0.75,"Strong",IF(K16>=0.4,"Moving","Early")) | N16: Kush | O16: =COUNTIF(GTM_Schedule!$H$5:$H$40,N16)-COUNTIFS(GTM_Schedule!$H$5:$H$40,N16,GTM_Schedule!$G$5:$G$40,"Done") | P16: =COUNTIFS(GTM_Schedule!$H$5:$H$40,N16,GTM_Schedule!$G$5:$G$40,"Done") | Q16: =IFERROR(O16/SUM($O$16:$O$19),0) | R16: =IF(O16=0,"Clear",IF(O16<=3,"Controlled","Loaded"))
B17: In Progress | C17: =COUNTIF(GTM_Schedule!$G$5:$G$40,B17) | D17: =IFERROR(C17/COUNTA(GTM_Schedule!$D$5:$D$40),0) | E17: Stable | F17: =REPT("|",ROUND(D17*20,0)) | H17: Phase 2 | I17: =COUNTIF(GTM_Schedule!$C$5:$C$40,"Phase 2*")-COUNTIFS(GTM_Schedule!$C$5:$C$40,"Phase 2*",GTM_Schedule!$G$5:$G$40,"Done") | J17: =COUNTIFS(GTM_Schedule!$C$5:$C$40,"Phase 2*",GTM_Schedule!$G$5:$G$40,"Done") | K17: =IFERROR(J17/(I17+J17),0) | L17: =IF(K17>=0.75,"Strong",IF(K17>=0.4,"Moving","Early")) | N17: Indu | O17: =COUNTIF(GTM_Schedule!$H$5:$H$40,N17)-COUNTIFS(GTM_Schedule!$H$5:$H$40,N17,GTM_Schedule!$G$5:$G$40,"Done") | P17: =COUNTIFS(GTM_Schedule!$H$5:$H$40,N17,GTM_Schedule!$G$5:$G$40,"Done") | Q17: =IFERROR(O17/SUM($O$16:$O$19),0) | R17: =IF(O17=0,"Clear",IF(O17<=3,"Controlled","Loaded"))
B18: Waiting | C18: =COUNTIF(GTM_Schedule!$G$5:$G$40,B18) | D18: =IFERROR(C18/COUNTA(GTM_Schedule!$D$5:$D$40),0) | E18: Attention | F18: =REPT("|",ROUND(D18*20,0)) | H18: Phase 3 | I18: =COUNTIF(GTM_Schedule!$C$5:$C$40,"Phase 3*")-COUNTIFS(GTM_Schedule!$C$5:$C$40,"Phase 3*",GTM_Schedule!$G$5:$G$40,"Done") | J18: =COUNTIFS(GTM_Schedule!$C$5:$C$40,"Phase 3*",GTM_Schedule!$G$5:$G$40,"Done") | K18: =IFERROR(J18/(I18+J18),0) | L18: =IF(K18>=0.75,"Strong",IF(K18>=0.4,"Moving","Early")) | N18: Codex | O18: =COUNTIF(GTM_Schedule!$H$5:$H$40,N18)-COUNTIFS(GTM_Schedule!$H$5:$H$40,N18,GTM_Schedule!$G$5:$G$40,"Done") | P18: =COUNTIFS(GTM_Schedule!$H$5:$H$40,N18,GTM_Schedule!$G$5:$G$40,"Done") | Q18: =IFERROR(O18/SUM($O$16:$O$19),0) | R18: =IF(O18=0,"Clear",IF(O18<=3,"Controlled","Loaded"))
B19: Blocked | C19: =COUNTIF(GTM_Schedule!$G$5:$G$40,B19) | D19: =IFERROR(C19/COUNTA(GTM_Schedule!$D$5:$D$40),0) | E19: Attention | F19: =REPT("|",ROUND(D19*20,0)) | H19: Phase 4 | I19: =COUNTIF(GTM_Schedule!$C$5:$C$40,"Phase 4*")-COUNTIFS(GTM_Schedule!$C$5:$C$40,"Phase 4*",GTM_Schedule!$G$5:$G$40,"Done") | J19: =COUNTIFS(GTM_Schedule!$C$5:$C$40,"Phase 4*",GTM_Schedule!$G$5:$G$40,"Done") | K19: =IFERROR(J19/(I19+J19),0) | L19: =IF(K19>=0.75,"Strong",IF(K19>=0.4,"Moving","Early")) | N19: Shared | O19: =COUNTIF(GTM_Schedule!$H$5:$H$40,N19)-COUNTIFS(GTM_Schedule!$H$5:$H$40,N19,GTM_Schedule!$G$5:$G$40,"Done") | P19: =COUNTIFS(GTM_Schedule!$H$5:$H$40,N19,GTM_Schedule!$G$5:$G$40,"Done") | Q19: =IFERROR(O19/SUM($O$16:$O$19),0) | R19: =IF(O19=0,"Clear",IF(O19<=3,"Controlled","Loaded"))
B20: Done | C20: =COUNTIF(GTM_Schedule!$G$5:$G$40,B20) | D20: =IFERROR(C20/COUNTA(GTM_Schedule!$D$5:$D$40),0) | E20: Stable | F20: =REPT("|",ROUND(D20*20,0)) | H20: Phase 5 | I20: =COUNTIF(GTM_Schedule!$C$5:$C$40,"Phase 5*")-COUNTIFS(GTM_Schedule!$C$5:$C$40,"Phase 5*",GTM_Schedule!$G$5:$G$40,"Done") | J20: =COUNTIFS(GTM_Schedule!$C$5:$C$40,"Phase 5*",GTM_Schedule!$G$5:$G$40,"Done") | K20: =IFERROR(J20/(I20+J20),0) | L20: =IF(K20>=0.75,"Strong",IF(K20>=0.4,"Moving","Early"))
H21: Phase 6 | I21: =COUNTIF(GTM_Schedule!$C$5:$C$40,"Phase 6*")-COUNTIFS(GTM_Schedule!$C$5:$C$40,"Phase 6*",GTM_Schedule!$G$5:$G$40,"Done") | J21: =COUNTIFS(GTM_Schedule!$C$5:$C$40,"Phase 6*",GTM_Schedule!$G$5:$G$40,"Done") | K21: =IFERROR(J21/(I21+J21),0) | L21: =IF(K21>=0.75,"Strong",IF(K21>=0.4,"Moving","Early"))
B24: Priority Focus Board | K24: Blocked / Waiting Watchlist
B25: Task | E25: Priority | K25: Task | N25: Priority
B26: =IFERROR(INDEX(GTM_Schedule!$D$5:$D$40,AGGREGATE(15,6,(ROW(GTM_Schedule!$D$5:$D$40)-ROW(GTM_Schedule!$D$5)+1)/((GTM_Schedule!$I$5:$I$40="High")*(GTM_Schedule!$G$5:$G$40<>"Done")),ROW(A26)-25)),"") | E26: =IF(B26="","",IFERROR(INDEX(GTM_Schedule!$C$5:$C$40,AGGREGATE(15,6,(ROW(GTM_Schedule!$C$5:$C$40)-ROW(GTM_Schedule!$C$5)+1)/((GTM_Schedule!$I$5:$I$40="High")*(GTM_Schedule!$G$5:$G$40<>"Done")),ROW(A26)-25)),"")) | G26: =IF(B26="","",IFERROR(INDEX(GTM_Schedule!$H$5:$H$40,AGGREGATE(15,6,(ROW(GTM_Schedule!$H$5:$H$40)-ROW(GTM_Schedule!$H$5)+1)/((GTM_Schedule!$I$5:$I$40="High")*(GTM_Schedule!$G$5:$G$40<>"Done")),ROW(A26)-25)),"")) | I26: =IF(B26="","",IFERROR(INDEX(GTM_Schedule!$I$5:$I$40,AGGREGATE(15,6,(ROW(GTM_Schedule!$I$5:$I$40)-ROW(GTM_Schedule!$I$5)+1)/((GTM_Schedule!$I$5:$I$40="High")*(GTM_Schedule!$G$5:$G$40<>"Done")),ROW(A26)-25)),"")) | K26: =IFERROR(INDEX(GTM_Schedule!$D$5:$D$40,AGGREGATE(15,6,(ROW(GTM_Schedule!$D$5:$D$40)-ROW(GTM_Schedule!$D$5)+1)/((GTM_Schedule!$G$5:$G$40="Blocked")+(GTM_Schedule!$G$5:$G$40="Waiting")),ROW(A26)-25)),"") | N26: =IF(K26="","",IFERROR(INDEX(GTM_Schedule!$G$5:$G$40,AGGREGATE(15,6,(ROW(GTM_Schedule!$G$5:$G$40)-ROW(GTM_Schedule!$G$5)+1)/((GTM_Schedule!$G$5:$G$40="Blocked")+(GTM_Schedule!$G$5:$G$40="Waiting")),ROW(A26)-25)),"")) | P26: =IF(K26="","",IFERROR(INDEX(GTM_Schedule!$H$5:$H$40,AGGREGATE(15,6,(ROW(GTM_Schedule!$H$5:$H$40)-ROW(GTM_Schedule!$H$5)+1)/((GTM_Schedule!$G$5:$G$40="Blocked")+(GTM_Schedule!$G$5:$G$40="Waiting")),ROW(A26)-25)),"")) | R26: =IF(K26="","",IFERROR(INDEX(GTM_Schedule!$I$5:$I$40,AGGREGATE(15,6,(ROW(GTM_Schedule!$I$5:$I$40)-ROW(GTM_Schedule!$I$5)+1)/((GTM_Schedule!$G$5:$G$40="Blocked")+(GTM_Schedule!$G$5:$G$40="Waiting")),ROW(A26)-25)),""))
B27: =IFERROR(INDEX(GTM_Schedule!$D$5:$D$40,AGGREGATE(15,6,(ROW(GTM_Schedule!$D$5:$D$40)-ROW(GTM_Schedule!$D$5)+1)/((GTM_Schedule!$I$5:$I$40="High")*(GTM_Schedule!$G$5:$G$40<>"Done")),ROW(A27)-25)),"") | E27: =IF(B27="","",IFERROR(INDEX(GTM_Schedule!$C$5:$C$40,AGGREGATE(15,6,(ROW(GTM_Schedule!$C$5:$C$40)-ROW(GTM_Schedule!$C$5)+1)/((GTM_Schedule!$I$5:$I$40="High")*(GTM_Schedule!$G$5:$G$40<>"Done")),ROW(A27)-25)),"")) | G27: =IF(B27="","",IFERROR(INDEX(GTM_Schedule!$H$5:$H$40,AGGREGATE(15,6,(ROW(GTM_Schedule!$H$5:$H$40)-ROW(GTM_Schedule!$H$5)+1)/((GTM_Schedule!$I$5:$I$40="High")*(GTM_Schedule!$G$5:$G$40<>"Done")),ROW(A27)-25)),"")) | I27: =IF(B27="","",IFERROR(INDEX(GTM_Schedule!$I$5:$I$40,AGGREGATE(15,6,(ROW(GTM_Schedule!$I$5:$I$40)-ROW(GTM_Schedule!$I$5)+1)/((GTM_Schedule!$I$5:$I$40="High")*(GTM_Schedule!$G$5:$G$40<>"Done")),ROW(A27)-25)),"")) | K27: =IFERROR(INDEX(GTM_Schedule!$D$5:$D$40,AGGREGATE(15,6,(ROW(GTM_Schedule!$D$5:$D$40)-ROW(GTM_Schedule!$D$5)+1)/((GTM_Schedule!$G$5:$G$40="Blocked")+(GTM_Schedule!$G$5:$G$40="Waiting")),ROW(A27)-25)),"") | N27: =IF(K27="","",IFERROR(INDEX(GTM_Schedule!$G$5:$G$40,AGGREGATE(15,6,(ROW(GTM_Schedule!$G$5:$G$40)-ROW(GTM_Schedule!$G$5)+1)/((GTM_Schedule!$G$5:$G$40="Blocked")+(GTM_Schedule!$G$5:$G$40="Waiting")),ROW(A27)-25)),"")) | P27: =IF(K27="","",IFERROR(INDEX(GTM_Schedule!$H$5:$H$40,AGGREGATE(15,6,(ROW(GTM_Schedule!$H$5:$H$40)-ROW(GTM_Schedule!$H$5)+1)/((GTM_Schedule!$G$5:$G$40="Blocked")+(GTM_Schedule!$G$5:$G$40="Waiting")),ROW(A27)-25)),"")) | R27: =IF(K27="","",IFERROR(INDEX(GTM_Schedule!$I$5:$I$40,AGGREGATE(15,6,(ROW(GTM_Schedule!$I$5:$I$40)-ROW(GTM_Schedule!$I$5)+1)/((GTM_Schedule!$G$5:$G$40="Blocked")+(GTM_Schedule!$G$5:$G$40="Waiting")),ROW(A27)-25)),""))
B28: =IFERROR(INDEX(GTM_Schedule!$D$5:$D$40,AGGREGATE(15,6,(ROW(GTM_Schedule!$D$5:$D$40)-ROW(GTM_Schedule!$D$5)+1)/((GTM_Schedule!$I$5:$I$40="High")*(GTM_Schedule!$G$5:$G$40<>"Done")),ROW(A28)-25)),"") | E28: =IF(B28="","",IFERROR(INDEX(GTM_Schedule!$C$5:$C$40,AGGREGATE(15,6,(ROW(GTM_Schedule!$C$5:$C$40)-ROW(GTM_Schedule!$C$5)+1)/((GTM_Schedule!$I$5:$I$40="High")*(GTM_Schedule!$G$5:$G$40<>"Done")),ROW(A28)-25)),"")) | G28: =IF(B28="","",IFERROR(INDEX(GTM_Schedule!$H$5:$H$40,AGGREGATE(15,6,(ROW(GTM_Schedule!$H$5:$H$40)-ROW(GTM_Schedule!$H$5)+1)/((GTM_Schedule!$I$5:$I$40="High")*(GTM_Schedule!$G$5:$G$40<>"Done")),ROW(A28)-25)),"")) | I28: =IF(B28="","",IFERROR(INDEX(GTM_Schedule!$I$5:$I$40,AGGREGATE(15,6,(ROW(GTM_Schedule!$I$5:$I$40)-ROW(GTM_Schedule!$I$5)+1)/((GTM_Schedule!$I$5:$I$40="High")*(GTM_Schedule!$G$5:$G$40<>"Done")),ROW(A28)-25)),"")) | K28: =IFERROR(INDEX(GTM_Schedule!$D$5:$D$40,AGGREGATE(15,6,(ROW(GTM_Schedule!$D$5:$D$40)-ROW(GTM_Schedule!$D$5)+1)/((GTM_Schedule!$G$5:$G$40="Blocked")+(GTM_Schedule!$G$5:$G$40="Waiting")),ROW(A28)-25)),"") | N28: =IF(K28="","",IFERROR(INDEX(GTM_Schedule!$G$5:$G$40,AGGREGATE(15,6,(ROW(GTM_Schedule!$G$5:$G$40)-ROW(GTM_Schedule!$G$5)+1)/((GTM_Schedule!$G$5:$G$40="Blocked")+(GTM_Schedule!$G$5:$G$40="Waiting")),ROW(A28)-25)),"")) | P28: =IF(K28="","",IFERROR(INDEX(GTM_Schedule!$H$5:$H$40,AGGREGATE(15,6,(ROW(GTM_Schedule!$H$5:$H$40)-ROW(GTM_Schedule!$H$5)+1)/((GTM_Schedule!$G$5:$G$40="Blocked")+(GTM_Schedule!$G$5:$G$40="Waiting")),ROW(A28)-25)),"")) | R28: =IF(K28="","",IFERROR(INDEX(GTM_Schedule!$I$5:$I$40,AGGREGATE(15,6,(ROW(GTM_Schedule!$I$5:$I$40)-ROW(GTM_Schedule!$I$5)+1)/((GTM_Schedule!$G$5:$G$40="Blocked")+(GTM_Schedule!$G$5:$G$40="Waiting")),ROW(A28)-25)),""))
B29: =IFERROR(INDEX(GTM_Schedule!$D$5:$D$40,AGGREGATE(15,6,(ROW(GTM_Schedule!$D$5:$D$40)-ROW(GTM_Schedule!$D$5)+1)/((GTM_Schedule!$I$5:$I$40="High")*(GTM_Schedule!$G$5:$G$40<>"Done")),ROW(A29)-25)),"") | E29: =IF(B29="","",IFERROR(INDEX(GTM_Schedule!$C$5:$C$40,AGGREGATE(15,6,(ROW(GTM_Schedule!$C$5:$C$40)-ROW(GTM_Schedule!$C$5)+1)/((GTM_Schedule!$I$5:$I$40="High")*(GTM_Schedule!$G$5:$G$40<>"Done")),ROW(A29)-25)),"")) | G29: =IF(B29="","",IFERROR(INDEX(GTM_Schedule!$H$5:$H$40,AGGREGATE(15,6,(ROW(GTM_Schedule!$H$5:$H$40)-ROW(GTM_Schedule!$H$5)+1)/((GTM_Schedule!$I$5:$I$40="High")*(GTM_Schedule!$G$5:$G$40<>"Done")),ROW(A29)-25)),"")) | I29: =IF(B29="","",IFERROR(INDEX(GTM_Schedule!$I$5:$I$40,AGGREGATE(15,6,(ROW(GTM_Schedule!$I$5:$I$40)-ROW(GTM_Schedule!$I$5)+1)/((GTM_Schedule!$I$5:$I$40="High")*(GTM_Schedule!$G$5:$G$40<>"Done")),ROW(A29)-25)),"")) | K29: =IFERROR(INDEX(GTM_Schedule!$D$5:$D$40,AGGREGATE(15,6,(ROW(GTM_Schedule!$D$5:$D$40)-ROW(GTM_Schedule!$D$5)+1)/((GTM_Schedule!$G$5:$G$40="Blocked")+(GTM_Schedule!$G$5:$G$40="Waiting")),ROW(A29)-25)),"") | N29: =IF(K29="","",IFERROR(INDEX(GTM_Schedule!$G$5:$G$40,AGGREGATE(15,6,(ROW(GTM_Schedule!$G$5:$G$40)-ROW(GTM_Schedule!$G$5)+1)/((GTM_Schedule!$G$5:$G$40="Blocked")+(GTM_Schedule!$G$5:$G$40="Waiting")),ROW(A29)-25)),"")) | P29: =IF(K29="","",IFERROR(INDEX(GTM_Schedule!$H$5:$H$40,AGGREGATE(15,6,(ROW(GTM_Schedule!$H$5:$H$40)-ROW(GTM_Schedule!$H$5)+1)/((GTM_Schedule!$G$5:$G$40="Blocked")+(GTM_Schedule!$G$5:$G$40="Waiting")),ROW(A29)-25)),"")) | R29: =IF(K29="","",IFERROR(INDEX(GTM_Schedule!$I$5:$I$40,AGGREGATE(15,6,(ROW(GTM_Schedule!$I$5:$I$40)-ROW(GTM_Schedule!$I$5)+1)/((GTM_Schedule!$G$5:$G$40="Blocked")+(GTM_Schedule!$G$5:$G$40="Waiting")),ROW(A29)-25)),""))
B30: =IFERROR(INDEX(GTM_Schedule!$D$5:$D$40,AGGREGATE(15,6,(ROW(GTM_Schedule!$D$5:$D$40)-ROW(GTM_Schedule!$D$5)+1)/((GTM_Schedule!$I$5:$I$40="High")*(GTM_Schedule!$G$5:$G$40<>"Done")),ROW(A30)-25)),"") | E30: =IF(B30="","",IFERROR(INDEX(GTM_Schedule!$C$5:$C$40,AGGREGATE(15,6,(ROW(GTM_Schedule!$C$5:$C$40)-ROW(GTM_Schedule!$C$5)+1)/((GTM_Schedule!$I$5:$I$40="High")*(GTM_Schedule!$G$5:$G$40<>"Done")),ROW(A30)-25)),"")) | G30: =IF(B30="","",IFERROR(INDEX(GTM_Schedule!$H$5:$H$40,AGGREGATE(15,6,(ROW(GTM_Schedule!$H$5:$H$40)-ROW(GTM_Schedule!$H$5)+1)/((GTM_Schedule!$I$5:$I$40="High")*(GTM_Schedule!$G$5:$G$40<>"Done")),ROW(A30)-25)),"")) | I30: =IF(B30="","",IFERROR(INDEX(GTM_Schedule!$I$5:$I$40,AGGREGATE(15,6,(ROW(GTM_Schedule!$I$5:$I$40)-ROW(GTM_Schedule!$I$5)+1)/((GTM_Schedule!$I$5:$I$40="High")*(GTM_Schedule!$G$5:$G$40<>"Done")),ROW(A30)-25)),"")) | K30: =IFERROR(INDEX(GTM_Schedule!$D$5:$D$40,AGGREGATE(15,6,(ROW(GTM_Schedule!$D$5:$D$40)-ROW(GTM_Schedule!$D$5)+1)/((GTM_Schedule!$G$5:$G$40="Blocked")+(GTM_Schedule!$G$5:$G$40="Waiting")),ROW(A30)-25)),"") | N30: =IF(K30="","",IFERROR(INDEX(GTM_Schedule!$G$5:$G$40,AGGREGATE(15,6,(ROW(GTM_Schedule!$G$5:$G$40)-ROW(GTM_Schedule!$G$5)+1)/((GTM_Schedule!$G$5:$G$40="Blocked")+(GTM_Schedule!$G$5:$G$40="Waiting")),ROW(A30)-25)),"")) | P30: =IF(K30="","",IFERROR(INDEX(GTM_Schedule!$H$5:$H$40,AGGREGATE(15,6,(ROW(GTM_Schedule!$H$5:$H$40)-ROW(GTM_Schedule!$H$5)+1)/((GTM_Schedule!$G$5:$G$40="Blocked")+(GTM_Schedule!$G$5:$G$40="Waiting")),ROW(A30)-25)),"")) | R30: =IF(K30="","",IFERROR(INDEX(GTM_Schedule!$I$5:$I$40,AGGREGATE(15,6,(ROW(GTM_Schedule!$I$5:$I$40)-ROW(GTM_Schedule!$I$5)+1)/((GTM_Schedule!$G$5:$G$40="Blocked")+(GTM_Schedule!$G$5:$G$40="Waiting")),ROW(A30)-25)),""))
B31: =IFERROR(INDEX(GTM_Schedule!$D$5:$D$40,AGGREGATE(15,6,(ROW(GTM_Schedule!$D$5:$D$40)-ROW(GTM_Schedule!$D$5)+1)/((GTM_Schedule!$I$5:$I$40="High")*(GTM_Schedule!$G$5:$G$40<>"Done")),ROW(A31)-25)),"") | E31: =IF(B31="","",IFERROR(INDEX(GTM_Schedule!$C$5:$C$40,AGGREGATE(15,6,(ROW(GTM_Schedule!$C$5:$C$40)-ROW(GTM_Schedule!$C$5)+1)/((GTM_Schedule!$I$5:$I$40="High")*(GTM_Schedule!$G$5:$G$40<>"Done")),ROW(A31)-25)),"")) | G31: =IF(B31="","",IFERROR(INDEX(GTM_Schedule!$H$5:$H$40,AGGREGATE(15,6,(ROW(GTM_Schedule!$H$5:$H$40)-ROW(GTM_Schedule!$H$5)+1)/((GTM_Schedule!$I$5:$I$40="High")*(GTM_Schedule!$G$5:$G$40<>"Done")),ROW(A31)-25)),"")) | I31: =IF(B31="","",IFERROR(INDEX(GTM_Schedule!$I$5:$I$40,AGGREGATE(15,6,(ROW(GTM_Schedule!$I$5:$I$40)-ROW(GTM_Schedule!$I$5)+1)/((GTM_Schedule!$I$5:$I$40="High")*(GTM_Schedule!$G$5:$G$40<>"Done")),ROW(A31)-25)),"")) | K31: =IFERROR(INDEX(GTM_Schedule!$D$5:$D$40,AGGREGATE(15,6,(ROW(GTM_Schedule!$D$5:$D$40)-ROW(GTM_Schedule!$D$5)+1)/((GTM_Schedule!$G$5:$G$40="Blocked")+(GTM_Schedule!$G$5:$G$40="Waiting")),ROW(A31)-25)),"") | N31: =IF(K31="","",IFERROR(INDEX(GTM_Schedule!$G$5:$G$40,AGGREGATE(15,6,(ROW(GTM_Schedule!$G$5:$G$40)-ROW(GTM_Schedule!$G$5)+1)/((GTM_Schedule!$G$5:$G$40="Blocked")+(GTM_Schedule!$G$5:$G$40="Waiting")),ROW(A31)-25)),"")) | P31: =IF(K31="","",IFERROR(INDEX(GTM_Schedule!$H$5:$H$40,AGGREGATE(15,6,(ROW(GTM_Schedule!$H$5:$H$40)-ROW(GTM_Schedule!$H$5)+1)/((GTM_Schedule!$G$5:$G$40="Blocked")+(GTM_Schedule!$G$5:$G$40="Waiting")),ROW(A31)-25)),"")) | R31: =IF(K31="","",IFERROR(INDEX(GTM_Schedule!$I$5:$I$40,AGGREGATE(15,6,(ROW(GTM_Schedule!$I$5:$I$40)-ROW(GTM_Schedule!$I$5)+1)/((GTM_Schedule!$G$5:$G$40="Blocked")+(GTM_Schedule!$G$5:$G$40="Waiting")),ROW(A31)-25)),""))
B32: =IFERROR(INDEX(GTM_Schedule!$D$5:$D$40,AGGREGATE(15,6,(ROW(GTM_Schedule!$D$5:$D$40)-ROW(GTM_Schedule!$D$5)+1)/((GTM_Schedule!$I$5:$I$40="High")*(GTM_Schedule!$G$5:$G$40<>"Done")),ROW(A32)-25)),"") | E32: =IF(B32="","",IFERROR(INDEX(GTM_Schedule!$C$5:$C$40,AGGREGATE(15,6,(ROW(GTM_Schedule!$C$5:$C$40)-ROW(GTM_Schedule!$C$5)+1)/((GTM_Schedule!$I$5:$I$40="High")*(GTM_Schedule!$G$5:$G$40<>"Done")),ROW(A32)-25)),"")) | G32: =IF(B32="","",IFERROR(INDEX(GTM_Schedule!$H$5:$H$40,AGGREGATE(15,6,(ROW(GTM_Schedule!$H$5:$H$40)-ROW(GTM_Schedule!$H$5)+1)/((GTM_Schedule!$I$5:$I$40="High")*(GTM_Schedule!$G$5:$G$40<>"Done")),ROW(A32)-25)),"")) | I32: =IF(B32="","",IFERROR(INDEX(GTM_Schedule!$I$5:$I$40,AGGREGATE(15,6,(ROW(GTM_Schedule!$I$5:$I$40)-ROW(GTM_Schedule!$I$5)+1)/((GTM_Schedule!$I$5:$I$40="High")*(GTM_Schedule!$G$5:$G$40<>"Done")),ROW(A32)-25)),"")) | K32: =IFERROR(INDEX(GTM_Schedule!$D$5:$D$40,AGGREGATE(15,6,(ROW(GTM_Schedule!$D$5:$D$40)-ROW(GTM_Schedule!$D$5)+1)/((GTM_Schedule!$G$5:$G$40="Blocked")+(GTM_Schedule!$G$5:$G$40="Waiting")),ROW(A32)-25)),"") | N32: =IF(K32="","",IFERROR(INDEX(GTM_Schedule!$G$5:$G$40,AGGREGATE(15,6,(ROW(GTM_Schedule!$G$5:$G$40)-ROW(GTM_Schedule!$G$5)+1)/((GTM_Schedule!$G$5:$G$40="Blocked")+(GTM_Schedule!$G$5:$G$40="Waiting")),ROW(A32)-25)),"")) | P32: =IF(K32="","",IFERROR(INDEX(GTM_Schedule!$H$5:$H$40,AGGREGATE(15,6,(ROW(GTM_Schedule!$H$5:$H$40)-ROW(GTM_Schedule!$H$5)+1)/((GTM_Schedule!$G$5:$G$40="Blocked")+(GTM_Schedule!$G$5:$G$40="Waiting")),ROW(A32)-25)),"")) | R32: =IF(K32="","",IFERROR(INDEX(GTM_Schedule!$I$5:$I$40,AGGREGATE(15,6,(ROW(GTM_Schedule!$I$5:$I$40)-ROW(GTM_Schedule!$I$5)+1)/((GTM_Schedule!$G$5:$G$40="Blocked")+(GTM_Schedule!$G$5:$G$40="Waiting")),ROW(A32)-25)),""))
B33: =IFERROR(INDEX(GTM_Schedule!$D$5:$D$40,AGGREGATE(15,6,(ROW(GTM_Schedule!$D$5:$D$40)-ROW(GTM_Schedule!$D$5)+1)/((GTM_Schedule!$I$5:$I$40="High")*(GTM_Schedule!$G$5:$G$40<>"Done")),ROW(A33)-25)),"") | E33: =IF(B33="","",IFERROR(INDEX(GTM_Schedule!$C$5:$C$40,AGGREGATE(15,6,(ROW(GTM_Schedule!$C$5:$C$40)-ROW(GTM_Schedule!$C$5)+1)/((GTM_Schedule!$I$5:$I$40="High")*(GTM_Schedule!$G$5:$G$40<>"Done")),ROW(A33)-25)),"")) | G33: =IF(B33="","",IFERROR(INDEX(GTM_Schedule!$H$5:$H$40,AGGREGATE(15,6,(ROW(GTM_Schedule!$H$5:$H$40)-ROW(GTM_Schedule!$H$5)+1)/((GTM_Schedule!$I$5:$I$40="High")*(GTM_Schedule!$G$5:$G$40<>"Done")),ROW(A33)-25)),"")) | I33: =IF(B33="","",IFERROR(INDEX(GTM_Schedule!$I$5:$I$40,AGGREGATE(15,6,(ROW(GTM_Schedule!$I$5:$I$40)-ROW(GTM_Schedule!$I$5)+1)/((GTM_Schedule!$I$5:$I$40="High")*(GTM_Schedule!$G$5:$G$40<>"Done")),ROW(A33)-25)),"")) | K33: =IFERROR(INDEX(GTM_Schedule!$D$5:$D$40,AGGREGATE(15,6,(ROW(GTM_Schedule!$D$5:$D$40)-ROW(GTM_Schedule!$D$5)+1)/((GTM_Schedule!$G$5:$G$40="Blocked")+(GTM_Schedule!$G$5:$G$40="Waiting")),ROW(A33)-25)),"") | N33: =IF(K33="","",IFERROR(INDEX(GTM_Schedule!$G$5:$G$40,AGGREGATE(15,6,(ROW(GTM_Schedule!$G$5:$G$40)-ROW(GTM_Schedule!$G$5)+1)/((GTM_Schedule!$G$5:$G$40="Blocked")+(GTM_Schedule!$G$5:$G$40="Waiting")),ROW(A33)-25)),"")) | P33: =IF(K33="","",IFERROR(INDEX(GTM_Schedule!$H$5:$H$40,AGGREGATE(15,6,(ROW(GTM_Schedule!$H$5:$H$40)-ROW(GTM_Schedule!$H$5)+1)/((GTM_Schedule!$G$5:$G$40="Blocked")+(GTM_Schedule!$G$5:$G$40="Waiting")),ROW(A33)-25)),"")) | R33: =IF(K33="","",IFERROR(INDEX(GTM_Schedule!$I$5:$I$40,AGGREGATE(15,6,(ROW(GTM_Schedule!$I$5:$I$40)-ROW(GTM_Schedule!$I$5)+1)/((GTM_Schedule!$G$5:$G$40="Blocked")+(GTM_Schedule!$G$5:$G$40="Waiting")),ROW(A33)-25)),""))

Sheet Influencer Hit List
A1: Name | B1: Channel Link | C1: Subscriber Count | D1: Business Email | E1: Niche | F1: Last Upload Topic | G1: Engagement Rate | H1: Status
A2: Arnab Nayak | B2: =IFERROR(__xludf.DUMMYFUNCTION("AI(""Fill an appropriate value for this cell based on the table context"")"),"https://www.youtube.com/@StartupGyaan") | C2: 85000 | D2: arnab@example.com | E2: Startups | F2: Startup Launch Guide | G2: 0.045 | H2: ⚪ New
A3: Ali Solanki | B3: =IFERROR(__xludf.DUMMYFUNCTION("AI(""Fill an appropriate value for this cell based on the table context"")"),"https://www.youtube.com/@StartupGyaan") | C3: 95000 | D3: ali@example.com | E3: Crypto/Tech | F3: Web3 Finance | G3: 0.055 | H3: ⚪ New
A4: Sushant Jain | B4: =IFERROR(__xludf.DUMMYFUNCTION("AI(""Fill an appropriate value for this cell based on the table context"")"),"https://www.youtube.com/@AliSolanki") | C4: 90000 | D4: sushant@example.com | E4: Stock Market | F4: Nifty Analysis | G4: 0.035 | H4: ⚪ New
A5: Riya Yadav | B5: =IFERROR(__xludf.DUMMYFUNCTION("AI(""Fill an appropriate value for this cell based on the table context"")"),"https://www.youtube.com/@AliSolanki") | C5: 75000 | D5: riya@example.com | E5: Crypto | F5: Bitcoin Halving | G5: 0.048 | H5: ⚪ New
A6: Yash Gupta | B6: =IFERROR(__xludf.DUMMYFUNCTION("AI(""Fill an appropriate value for this cell based on the table context"")"),"https://www.youtube.com/@riyayadav") | C6: 60000 | D6: yash@example.com | E6: Money Management | F6: Top 5 SIPs | G6: 0.038 | H6: ⚪ New
A7: Kiran | B7: =IFERROR(__xludf.DUMMYFUNCTION("AI(""Fill an appropriate value for this cell based on the table context"")"),"I do not have enough information to provide the specific YouTube channel link for the Yash Gupta mentioned in your spreadsheet. While there are several creators with this name, none of the available search results match a channel with 60,000 subscribers s"&"pecializing in Money Management and SIPs. To help me find the correct link, please provide the specific YouTube handle or a unique identifier for this creator.") | C7: 50000 | D7: kiran@example.com | E7: Financial Independence | F7: FIRE Movement | G7: 0.04 | H7: ⚪ New
A8: Brahmi Kapasi | B8: =IFERROR(__xludf.DUMMYFUNCTION("AI(""Fill an appropriate value for this cell based on the table context"")"),"https://www.youtube.com/@kiranroy") | C8: 45000 | D8: brahmi@example.com | E8: Personal Finance | F8: Budgeting 101 | G8: 0.052 | H8: ⚪ New
A9: Shivam Chhuneja | B9: =IFERROR(__xludf.DUMMYFUNCTION("AI(""Fill an appropriate value for this cell based on the table context"")"),"https://www.youtube.com/@TravelwithBrahmi") | C9: 40000 | D9: shivam@example.com | E9: Crypto Education | F9: Avoiding Scams | G9: 0.033 | H9: ⚪ New
A10: Ishaan Arora | B10: =IFERROR(__xludf.DUMMYFUNCTION("AI(""Fill an appropriate value for this cell based on the table context"")"),"https://www.youtube.com/@shivamchhuneja") | C10: 30000 | D10: ishaan@example.com | E10: Trading | F10: Options Hedging | G10: 0.061 | H10: ⚪ New
A11: Aashutosh Singla | B11: =IFERROR(__xludf.DUMMYFUNCTION("AI(""Fill an appropriate value for this cell based on the table context"")"),"https://www.youtube.com/@ishaanarora.official") | C11: 25000 | D11: aashutosh@example.com | E11: Finance Guide | F11: Investing for Beginners | G11: 0.059 | H11: ⚪ New
A12: Ujjwal Pahwa | B12: =IFERROR(__xludf.DUMMYFUNCTION("AI(""Fill an appropriate value for this cell based on the table context"")"),"https://www.youtube.com/@AashutoshSingla") | C12: 82000 | D12: ujjwal@example.com | E12: Finance/Careers | F12: Best Credit Cards | G12: 0.042 | H12: =IFERROR(__xludf.DUMMYFUNCTION("AI(""Fill an appropriate value for this cell based on the table context"")"),"⚪ New")
A13: Chhavi Agarwal | B13: =IFERROR(__xludf.DUMMYFUNCTION("AI(""Fill an appropriate value for this cell based on the table context"")"),"https://www.youtube.com/@AashutoshSingla") | C13: 48000 | D13: chhavi@example.com | E13: Stock Market | F13: IPO Reviews | G13: 0.051 | H13: =IFERROR(__xludf.DUMMYFUNCTION("AI(""Fill an appropriate value for this cell based on the table context"")"),"⚪ New")
A14: Vanshree Bajaj | B14: =IFERROR(__xludf.DUMMYFUNCTION("AI(""Fill an appropriate value for this cell based on the table context"")"),"https://www.youtube.com/@chhavibsht") | C14: 35000 | D14: vanshree@example.com | E14: Taxation/Investing | F14: Tax Saving Hacks | G14: 0.039 | H14: =IFERROR(__xludf.DUMMYFUNCTION("AI(""Fill an appropriate value for this cell based on the table context"")"),"⚪ New")
A15: Gauri Punjabi | B15: =IFERROR(__xludf.DUMMYFUNCTION("AI(""Fill an appropriate value for this cell based on the table context"")"),"https://www.youtube.com/@vanshreebajaj") | C15: 22000 | D15: gauri@example.com | E15: Personal Finance | F15: Budgeting for Gen Z | G15: 0.047 | H15: =IFERROR(__xludf.DUMMYFUNCTION("AI(""Fill an appropriate value for this cell based on the table context"")"),"⚪ New")
A16: Esha Choudhary | B16: =IFERROR(__xludf.DUMMYFUNCTION("AI(""Fill an appropriate value for this cell based on the table context"")"),"https://www.youtube.com/@gauripunjabi") | C16: 65000 | D16: esha@example.com | E16: Investing | F16: Mutual Fund Analysis | G16: 0.043 | H16: =IFERROR(__xludf.DUMMYFUNCTION("AI(""Fill an appropriate value for this cell based on the table context"")"),"⚪ New")
A17: Tarun Jagdish | B17: =IFERROR(__xludf.DUMMYFUNCTION("AI(""Fill an appropriate value for this cell based on the table context"")"),"https://www.youtube.com/@eshachoudhary") | C17: 15000 | D17: tarun@example.com | E17: Day Trading | F17: Candlestick Patterns | G17: 0.065 | H17: =IFERROR(__xludf.DUMMYFUNCTION("AI(""Fill an appropriate value for this cell based on the table context"")"),"⚪ New")
A18: Finance with Aarati | B18: =IFERROR(__xludf.DUMMYFUNCTION("AI(""Fill an appropriate value for this cell based on the table context"")"),"https://www.youtube.com/@CATARUNJAGDISH") | C18: 28000 | D18: aarati@example.com | E18: Savings | F18: Gold vs Stocks | G18: 0.04 | H18: =IFERROR(__xludf.DUMMYFUNCTION("AI(""Fill an appropriate value for this cell based on the table context"")"),"⚪ New")
A19: Anamika | B19: =IFERROR(__xludf.DUMMYFUNCTION("AI(""Fill an appropriate value for this cell based on the table context"")"),"https://www.youtube.com/@BusinessLine") | C19: 12000 | D19: anamika@example.com | E19: Beginner Finance | F19: Opening Demat Account | G19: 0.055 | H19: =IFERROR(__xludf.DUMMYFUNCTION("AI(""Fill an appropriate value for this cell based on the table context"")"),"⚪ New")
A20: Kushal Lodha | B20: =IFERROR(__xludf.DUMMYFUNCTION("AI(""Fill an appropriate value for this cell based on the table context"")"),"https://www.youtube.com/@Anamika_18") | C20: 98000 | D20: kushal@example.com | E20: Career/Finance | F20: Salary Negotiations | G20: 0.032 | H20: =IFERROR(__xludf.DUMMYFUNCTION("AI(""Fill an appropriate value for this cell based on the table context"")"),"⚪ New")
A21: Aditya Saini | B21: =IFERROR(__xludf.DUMMYFUNCTION("AI(""Fill an appropriate value for this cell based on the table context"")"),"https://www.youtube.com/@KushalLodha548") | C21: 75000 | D21: aditya@example.com | E21: Trading News | F21: Market Wrap-up | G21: 0.038 | H21: =IFERROR(__xludf.DUMMYFUNCTION("AI(""Fill an appropriate value for this cell based on the table context"")"),"⚪ New")

Sheet Referral & Revenue Tracker
A1: Partner Name | B1: Custom Slug | C1: Total Clicks | D1: Signups | E1: Activations | F1: Commission Earned
A2: Arnab Nayak | B2: fnomo-arnab | C2: 1500 | D2: 300 | E2: 50 | F2: =E2*200
A3: Brahmi Kapasi | B3: fnomo-brahmi | C3: 800 | D3: 150 | E3: 20 | F3: =E3*200
A4: Yash Gupta | B4: fnomo-yash | C4: 1200 | D4: 200 | E4: 35 | F4: =E4*200

Sheet Social Proof Repository
A1: User ID | B1: Decision Moment | C1: Fnomo Score | D1: Risk Level | E1: The Outcome | F1: Narrative Story
A2: U-101 | B2: Paytm IPO | C2: 3 | D2: High | E2: Avoided buying at listing | F2: I was caught up in the hype and almost bought Paytm on listing day. Fnomo's low score made me wait, saving me from a massive 30% drop.
A3: U-102 | B3: HDFC Bank Dip | C3: 8 | D3: Low | E3: Bought the dip | F3: HDFC Bank was falling and I was panicking to sell. Fnomo highlighted the strong fundamentals and low risk, giving me the confidence to buy more instead.
A4: U-103 | B4: Random Crypto Coin | C4: 2 | D4: Very High | E4: Cancelled order | F4: A friend recommended a new crypto coin that was trending on Twitter. Fnomo flagged it as a high-risk speculative asset, so I cancelled my buy order and avoided a rug pull.

Sheet Corporate Pilot Outreach
B2: CORPORATE PILOT: LEADERSHIP SESSIONS
B3: Setup (Green) | Outreach (Purple) | Meeting (Yellow) | Closed (Orange)
B5: Lead ID | C5: Status | D5: Company Name | E5: HR/Leadership Contact | F5: Decision Proximity (1-10) | G5: Sent Date | H5: Email/LinkedIn | I5: Feedback/Notes
B6: 1 | C6: ⚪ New | D6: Tata | I6: Leadership Investing Session
B7: 2 | C7: ⚪ New | D7: Infosys | I7: Leadership Investing Session
B8: 3 | C8: ⚪ New | D8: Reliance | I8: Leadership Investing Session

Sheet Telegram_War_Room
B2: TELEGRAM: ADMIN & COMMUNITY OUTREACH
B3: Setup (Green) | Outreach (Purple) | Meeting (Yellow) | Closed (Orange)
B5: Lead ID | C5: Status | D5: Group Name | E5: Admin Handle (@) | F5: Decision Proximity (1-10) | G5: Influence Score | H5: The Hook | I5: Next Action
B6: =IFERROR(__xludf.DUMMYFUNCTION("IFERROR(CHOOSECOLS(FILTER(Outreach_Database!A2:R1000, Outreach_Database!I2:I1000=""Telegram""), 1, 2, 5, 15, 16, 18, 17, 13), ""No data found"")"),51) | C6: =IFERROR(__xludf.DUMMYFUNCTION("""COMPUTED_VALUE"""),"⚪ New") | D6: =IFERROR(__xludf.DUMMYFUNCTION("""COMPUTED_VALUE"""),"Nifty Stock Trades")
B7: =IFERROR(__xludf.DUMMYFUNCTION("""COMPUTED_VALUE"""),52) | C7: =IFERROR(__xludf.DUMMYFUNCTION("""COMPUTED_VALUE"""),"⚪ New") | D7: =IFERROR(__xludf.DUMMYFUNCTION("""COMPUTED_VALUE"""),"Esha Analysis")
B8: =IFERROR(__xludf.DUMMYFUNCTION("""COMPUTED_VALUE"""),53) | C8: =IFERROR(__xludf.DUMMYFUNCTION("""COMPUTED_VALUE"""),"⚪ New") | D8: =IFERROR(__xludf.DUMMYFUNCTION("""COMPUTED_VALUE"""),"Vijay Wealth Advisor")
B9: =IFERROR(__xludf.DUMMYFUNCTION("""COMPUTED_VALUE"""),54) | C9: =IFERROR(__xludf.DUMMYFUNCTION("""COMPUTED_VALUE"""),"⚪ New") | D9: =IFERROR(__xludf.DUMMYFUNCTION("""COMPUTED_VALUE"""),"Trading Saint Official")
B10: =IFERROR(__xludf.DUMMYFUNCTION("""COMPUTED_VALUE"""),55) | C10: =IFERROR(__xludf.DUMMYFUNCTION("""COMPUTED_VALUE"""),"⚪ New") | D10: =IFERROR(__xludf.DUMMYFUNCTION("""COMPUTED_VALUE"""),"Share Stock Market Calls")
B11: =IFERROR(__xludf.DUMMYFUNCTION("""COMPUTED_VALUE"""),56) | C11: =IFERROR(__xludf.DUMMYFUNCTION("""COMPUTED_VALUE"""),"⚪ New") | D11: =IFERROR(__xludf.DUMMYFUNCTION("""COMPUTED_VALUE"""),"Trade Watcher")
B12: =IFERROR(__xludf.DUMMYFUNCTION("""COMPUTED_VALUE"""),57) | C12: =IFERROR(__xludf.DUMMYFUNCTION("""COMPUTED_VALUE"""),"⚪ New") | D12: =IFERROR(__xludf.DUMMYFUNCTION("""COMPUTED_VALUE"""),"Daily Option Profit")
B13: =IFERROR(__xludf.DUMMYFUNCTION("""COMPUTED_VALUE"""),58) | C13: =IFERROR(__xludf.DUMMYFUNCTION("""COMPUTED_VALUE"""),"⚪ New") | D13: =IFERROR(__xludf.DUMMYFUNCTION("""COMPUTED_VALUE"""),"Chawla Stock Market")
B14: =IFERROR(__xludf.DUMMYFUNCTION("""COMPUTED_VALUE"""),59) | C14: =IFERROR(__xludf.DUMMYFUNCTION("""COMPUTED_VALUE"""),"⚪ New") | D14: =IFERROR(__xludf.DUMMYFUNCTION("""COMPUTED_VALUE"""),"ASHA Stock Market")
B15: =IFERROR(__xludf.DUMMYFUNCTION("""COMPUTED_VALUE"""),60) | C15: =IFERROR(__xludf.DUMMYFUNCTION("""COMPUTED_VALUE"""),"⚪ New") | D15: =IFERROR(__xludf.DUMMYFUNCTION("""COMPUTED_VALUE"""),"IPO Ji ™️")
B16: =IFERROR(__xludf.DUMMYFUNCTION("""COMPUTED_VALUE"""),61) | C16: =IFERROR(__xludf.DUMMYFUNCTION("""COMPUTED_VALUE"""),"⚪ New") | D16: =IFERROR(__xludf.DUMMYFUNCTION("""COMPUTED_VALUE"""),"Trading with CA Abhay")
B17: =IFERROR(__xludf.DUMMYFUNCTION("""COMPUTED_VALUE"""),62) | C17: =IFERROR(__xludf.DUMMYFUNCTION("""COMPUTED_VALUE"""),"⚪ New") | D17: =IFERROR(__xludf.DUMMYFUNCTION("""COMPUTED_VALUE"""),"Index Trading (Nitin Murarka)")
B18: =IFERROR(__xludf.DUMMYFUNCTION("""COMPUTED_VALUE"""),63) | C18: =IFERROR(__xludf.DUMMYFUNCTION("""COMPUTED_VALUE"""),"⚪ New") | D18: =IFERROR(__xludf.DUMMYFUNCTION("""COMPUTED_VALUE"""),"Whale Alert")
B19: =IFERROR(__xludf.DUMMYFUNCTION("""COMPUTED_VALUE"""),64) | C19: =IFERROR(__xludf.DUMMYFUNCTION("""COMPUTED_VALUE"""),"⚪ New") | D19: =IFERROR(__xludf.DUMMYFUNCTION("""COMPUTED_VALUE"""),"CoinCodex")
B20: =IFERROR(__xludf.DUMMYFUNCTION("""COMPUTED_VALUE"""),65) | C20: =IFERROR(__xludf.DUMMYFUNCTION("""COMPUTED_VALUE"""),"⚪ New") | D20: =IFERROR(__xludf.DUMMYFUNCTION("""COMPUTED_VALUE"""),"The Block News")
B21: =IFERROR(__xludf.DUMMYFUNCTION("""COMPUTED_VALUE"""),66) | C21: =IFERROR(__xludf.DUMMYFUNCTION("""COMPUTED_VALUE"""),"⚪ New") | D21: =IFERROR(__xludf.DUMMYFUNCTION("""COMPUTED_VALUE"""),"Binance Killers")
B22: =IFERROR(__xludf.DUMMYFUNCTION("""COMPUTED_VALUE"""),67) | C22: =IFERROR(__xludf.DUMMYFUNCTION("""COMPUTED_VALUE"""),"⚪ New") | D22: =IFERROR(__xludf.DUMMYFUNCTION("""COMPUTED_VALUE"""),"Wolf of Trading")
B23: =IFERROR(__xludf.DUMMYFUNCTION("""COMPUTED_VALUE"""),68) | C23: =IFERROR(__xludf.DUMMYFUNCTION("""COMPUTED_VALUE"""),"⚪ New") | D23: =IFERROR(__xludf.DUMMYFUNCTION("""COMPUTED_VALUE"""),"Crypto Inner Circle")
B24: =IFERROR(__xludf.DUMMYFUNCTION("""COMPUTED_VALUE"""),69) | C24: =IFERROR(__xludf.DUMMYFUNCTION("""COMPUTED_VALUE"""),"⚪ New") | D24: =IFERROR(__xludf.DUMMYFUNCTION("""COMPUTED_VALUE"""),"Bitcoin Bullets")
B25: =IFERROR(__xludf.DUMMYFUNCTION("""COMPUTED_VALUE"""),70) | C25: =IFERROR(__xludf.DUMMYFUNCTION("""COMPUTED_VALUE"""),"⚪ New") | D25: =IFERROR(__xludf.DUMMYFUNCTION("""COMPUTED_VALUE"""),"Wall Street Queen")
B26: =IFERROR(__xludf.DUMMYFUNCTION("""COMPUTED_VALUE"""),71) | C26: =IFERROR(__xludf.DUMMYFUNCTION("""COMPUTED_VALUE"""),"⚪ New") | D26: =IFERROR(__xludf.DUMMYFUNCTION("""COMPUTED_VALUE"""),"Stock Market Adda")
B27: =IFERROR(__xludf.DUMMYFUNCTION("""COMPUTED_VALUE"""),72) | C27: =IFERROR(__xludf.DUMMYFUNCTION("""COMPUTED_VALUE"""),"⚪ New") | D27: =IFERROR(__xludf.DUMMYFUNCTION("""COMPUTED_VALUE"""),"Dark Horse of Stock Market")
B28: =IFERROR(__xludf.DUMMYFUNCTION("""COMPUTED_VALUE"""),73) | C28: =IFERROR(__xludf.DUMMYFUNCTION("""COMPUTED_VALUE"""),"⚪ New") | D28: =IFERROR(__xludf.DUMMYFUNCTION("""COMPUTED_VALUE"""),"Mr Scalper Official")
B29: =IFERROR(__xludf.DUMMYFUNCTION("""COMPUTED_VALUE"""),74) | C29: =IFERROR(__xludf.DUMMYFUNCTION("""COMPUTED_VALUE"""),"⚪ New") | D29: =IFERROR(__xludf.DUMMYFUNCTION("""COMPUTED_VALUE"""),"20PAISA.COM")
B30: =IFERROR(__xludf.DUMMYFUNCTION("""COMPUTED_VALUE"""),75) | C30: =IFERROR(__xludf.DUMMYFUNCTION("""COMPUTED_VALUE"""),"⚪ New") | D30: =IFERROR(__xludf.DUMMYFUNCTION("""COMPUTED_VALUE"""),"Bharath's Market Research")
B31: =IFERROR(__xludf.DUMMYFUNCTION("""COMPUTED_VALUE"""),76) | C31: =IFERROR(__xludf.DUMMYFUNCTION("""COMPUTED_VALUE"""),"⚪ New") | D31: =IFERROR(__xludf.DUMMYFUNCTION("""COMPUTED_VALUE"""),"Stockizen Research")
B32: =IFERROR(__xludf.DUMMYFUNCTION("""COMPUTED_VALUE"""),77) | C32: =IFERROR(__xludf.DUMMYFUNCTION("""COMPUTED_VALUE"""),"⚪ New") | D32: =IFERROR(__xludf.DUMMYFUNCTION("""COMPUTED_VALUE"""),"Eqwires Research")
B33: =IFERROR(__xludf.DUMMYFUNCTION("""COMPUTED_VALUE"""),78) | C33: =IFERROR(__xludf.DUMMYFUNCTION("""COMPUTED_VALUE"""),"⚪ New") | D33: =IFERROR(__xludf.DUMMYFUNCTION("""COMPUTED_VALUE"""),"StockYaari Premium")
B34: =IFERROR(__xludf.DUMMYFUNCTION("""COMPUTED_VALUE"""),79) | C34: =IFERROR(__xludf.DUMMYFUNCTION("""COMPUTED_VALUE"""),"⚪ New") | D34: =IFERROR(__xludf.DUMMYFUNCTION("""COMPUTED_VALUE"""),"Flying Calls")
B35: =IFERROR(__xludf.DUMMYFUNCTION("""COMPUTED_VALUE"""),80) | C35: =IFERROR(__xludf.DUMMYFUNCTION("""COMPUTED_VALUE"""),"⚪ New") | D35: =IFERROR(__xludf.DUMMYFUNCTION("""COMPUTED_VALUE"""),"Rakesh Bansal Ventures")
B36: =IFERROR(__xludf.DUMMYFUNCTION("""COMPUTED_VALUE"""),81) | C36: =IFERROR(__xludf.DUMMYFUNCTION("""COMPUTED_VALUE"""),"⚪ New") | D36: =IFERROR(__xludf.DUMMYFUNCTION("""COMPUTED_VALUE"""),"IPO GMP Updates")
B37: =IFERROR(__xludf.DUMMYFUNCTION("""COMPUTED_VALUE"""),82) | C37: =IFERROR(__xludf.DUMMYFUNCTION("""COMPUTED_VALUE"""),"⚪ New") | D37: =IFERROR(__xludf.DUMMYFUNCTION("""COMPUTED_VALUE"""),"Mutual Fund Guides India")
B38: =IFERROR(__xludf.DUMMYFUNCTION("""COMPUTED_VALUE"""),83) | C38: =IFERROR(__xludf.DUMMYFUNCTION("""COMPUTED_VALUE"""),"⚪ New") | D38: =IFERROR(__xludf.DUMMYFUNCTION("""COMPUTED_VALUE"""),"Zerodha Traders Hub")
B39: =IFERROR(__xludf.DUMMYFUNCTION("""COMPUTED_VALUE"""),84) | C39: =IFERROR(__xludf.DUMMYFUNCTION("""COMPUTED_VALUE"""),"⚪ New") | D39: =IFERROR(__xludf.DUMMYFUNCTION("""COMPUTED_VALUE"""),"Upstox Power Traders")
B40: =IFERROR(__xludf.DUMMYFUNCTION("""COMPUTED_VALUE"""),85) | C40: =IFERROR(__xludf.DUMMYFUNCTION("""COMPUTED_VALUE"""),"⚪ New") | D40: =IFERROR(__xludf.DUMMYFUNCTION("""COMPUTED_VALUE"""),"Groww Investors Club")
B41: =IFERROR(__xludf.DUMMYFUNCTION("""COMPUTED_VALUE"""),86) | C41: =IFERROR(__xludf.DUMMYFUNCTION("""COMPUTED_VALUE"""),"⚪ New") | D41: =IFERROR(__xludf.DUMMYFUNCTION("""COMPUTED_VALUE"""),"Nifty Options Pro")
B42: =IFERROR(__xludf.DUMMYFUNCTION("""COMPUTED_VALUE"""),87) | C42: =IFERROR(__xludf.DUMMYFUNCTION("""COMPUTED_VALUE"""),"⚪ New") | D42: =IFERROR(__xludf.DUMMYFUNCTION("""COMPUTED_VALUE"""),"Bank Nifty Specialists")
...

Sheet Reddit_War_Room
B2: REDDIT: SUBREDDIT & ADVICE THREADS
B3: Setup (Green) | Outreach (Purple) | Meeting (Yellow) | Closed (Orange)
B5: Lead ID | C5: Status | D5: Subreddit | E5: Moderator/Target | F5: Decision Proximity | G5: Karma/Influence | H5: The Hook | I5: Post/Comment Link
B6: =IFERROR(__xludf.DUMMYFUNCTION("IFERROR(CHOOSECOLS(FILTER(Outreach_Database!A2:R1000, Outreach_Database!I2:I1000=""Reddit""), 1, 2, 5, 15, 16, 18, 17, 8), ""No data found"")"),1) | C6: =IFERROR(__xludf.DUMMYFUNCTION("""COMPUTED_VALUE"""),"⚪ New") | D6: =IFERROR(__xludf.DUMMYFUNCTION("""COMPUTED_VALUE"""),"r/IndiaInvestments") | I6: =IFERROR(__xludf.DUMMYFUNCTION("""COMPUTED_VALUE"""),"https://www.reddit.com/r/IndiaInvestments/")
B7: =IFERROR(__xludf.DUMMYFUNCTION("""COMPUTED_VALUE"""),2) | C7: =IFERROR(__xludf.DUMMYFUNCTION("""COMPUTED_VALUE"""),"⚪ New") | D7: =IFERROR(__xludf.DUMMYFUNCTION("""COMPUTED_VALUE"""),"r/IndianStreetBets") | I7: =IFERROR(__xludf.DUMMYFUNCTION("""COMPUTED_VALUE"""),"https://www.reddit.com/r/IndianStreetBets/")
B8: =IFERROR(__xludf.DUMMYFUNCTION("""COMPUTED_VALUE"""),3) | C8: =IFERROR(__xludf.DUMMYFUNCTION("""COMPUTED_VALUE"""),"⚪ New") | D8: =IFERROR(__xludf.DUMMYFUNCTION("""COMPUTED_VALUE"""),"r/PersonalFinanceIndia") | I8: =IFERROR(__xludf.DUMMYFUNCTION("""COMPUTED_VALUE"""),"https://www.reddit.com/r/personalfinanceindia/")
B9: =IFERROR(__xludf.DUMMYFUNCTION("""COMPUTED_VALUE"""),4) | C9: =IFERROR(__xludf.DUMMYFUNCTION("""COMPUTED_VALUE"""),"⚪ New") | D9: =IFERROR(__xludf.DUMMYFUNCTION("""COMPUTED_VALUE"""),"r/Indiantradingbets") | I9: =IFERROR(__xludf.DUMMYFUNCTION("""COMPUTED_VALUE"""),"https://www.reddit.com/r/Indiantradingbets/")
B10: =IFERROR(__xludf.DUMMYFUNCTION("""COMPUTED_VALUE"""),5) | C10: =IFERROR(__xludf.DUMMYFUNCTION("""COMPUTED_VALUE"""),"⚪ New") | D10: =IFERROR(__xludf.DUMMYFUNCTION("""COMPUTED_VALUE"""),"r/dalalstreetbets") | I10: =IFERROR(__xludf.DUMMYFUNCTION("""COMPUTED_VALUE"""),"https://www.reddit.com/r/dalalstreetbets/")
B11: =IFERROR(__xludf.DUMMYFUNCTION("""COMPUTED_VALUE"""),6) | C11: =IFERROR(__xludf.DUMMYFUNCTION("""COMPUTED_VALUE"""),"⚪ New") | D11: =IFERROR(__xludf.DUMMYFUNCTION("""COMPUTED_VALUE"""),"r/StockMarketIndia") | I11: =IFERROR(__xludf.DUMMYFUNCTION("""COMPUTED_VALUE"""),"https://www.reddit.com/r/StockMarketIndia/")
B12: =IFERROR(__xludf.DUMMYFUNCTION("""COMPUTED_VALUE"""),7) | C12: =IFERROR(__xludf.DUMMYFUNCTION("""COMPUTED_VALUE"""),"⚪ New") | D12: =IFERROR(__xludf.DUMMYFUNCTION("""COMPUTED_VALUE"""),"r/FIREIndia") | I12: =IFERROR(__xludf.DUMMYFUNCTION("""COMPUTED_VALUE"""),"https://www.reddit.com/r/FIREIndia/")
B13: =IFERROR(__xludf.DUMMYFUNCTION("""COMPUTED_VALUE"""),8) | C13: =IFERROR(__xludf.DUMMYFUNCTION("""COMPUTED_VALUE"""),"⚪ New") | D13: =IFERROR(__xludf.DUMMYFUNCTION("""COMPUTED_VALUE"""),"r/IndiaTax") | I13: =IFERROR(__xludf.DUMMYFUNCTION("""COMPUTED_VALUE"""),"https://www.reddit.com/r/IndiaTax/")
B14: =IFERROR(__xludf.DUMMYFUNCTION("""COMPUTED_VALUE"""),9) | C14: =IFERROR(__xludf.DUMMYFUNCTION("""COMPUTED_VALUE"""),"⚪ New") | D14: =IFERROR(__xludf.DUMMYFUNCTION("""COMPUTED_VALUE"""),"r/IndiaCreditCards") | I14: =IFERROR(__xludf.DUMMYFUNCTION("""COMPUTED_VALUE"""),"https://www.google.com/search?q=https://www.reddit.com/r/IndiaCreditCards/")
B15: =IFERROR(__xludf.DUMMYFUNCTION("""COMPUTED_VALUE"""),10) | C15: =IFERROR(__xludf.DUMMYFUNCTION("""COMPUTED_VALUE"""),"⚪ New") | D15: =IFERROR(__xludf.DUMMYFUNCTION("""COMPUTED_VALUE"""),"r/StartupIndia") | I15: =IFERROR(__xludf.DUMMYFUNCTION("""COMPUTED_VALUE"""),"https://www.reddit.com/r/StartupIndia/")
B16: =IFERROR(__xludf.DUMMYFUNCTION("""COMPUTED_VALUE"""),11) | C16: =IFERROR(__xludf.DUMMYFUNCTION("""COMPUTED_VALUE"""),"⚪ New") | D16: =IFERROR(__xludf.DUMMYFUNCTION("""COMPUTED_VALUE"""),"r/MutualFundsIndia") | I16: =IFERROR(__xludf.DUMMYFUNCTION("""COMPUTED_VALUE"""),"https://www.reddit.com/r/MutualFundsIndia/")
B17: =IFERROR(__xludf.DUMMYFUNCTION("""COMPUTED_VALUE"""),12) | C17: =IFERROR(__xludf.DUMMYFUNCTION("""COMPUTED_VALUE"""),"⚪ New") | D17: =IFERROR(__xludf.DUMMYFUNCTION("""COMPUTED_VALUE"""),"r/IndiaMarket") | I17: =IFERROR(__xludf.DUMMYFUNCTION("""COMPUTED_VALUE"""),"https://www.google.com/search?q=https://www.reddit.com/r/IndiaMarket/")
B18: =IFERROR(__xludf.DUMMYFUNCTION("""COMPUTED_VALUE"""),13) | C18: =IFERROR(__xludf.DUMMYFUNCTION("""COMPUTED_VALUE"""),"⚪ New") | D18: =IFERROR(__xludf.DUMMYFUNCTION("""COMPUTED_VALUE"""),"r/BusinessIndia") | I18: =IFERROR(__xludf.DUMMYFUNCTION("""COMPUTED_VALUE"""),"https://www.google.com/search?q=https://www.reddit.com/r/BusinessIndia/")
B19: =IFERROR(__xludf.DUMMYFUNCTION("""COMPUTED_VALUE"""),14) | C19: =IFERROR(__xludf.DUMMYFUNCTION("""COMPUTED_VALUE"""),"⚪ New") | D19: =IFERROR(__xludf.DUMMYFUNCTION("""COMPUTED_VALUE"""),"r/Nifty50") | I19: =IFERROR(__xludf.DUMMYFUNCTION("""COMPUTED_VALUE"""),"https://www.google.com/search?q=https://www.reddit.com/r/Nifty50/")
B20: =IFERROR(__xludf.DUMMYFUNCTION("""COMPUTED_VALUE"""),15) | C20: =IFERROR(__xludf.DUMMYFUNCTION("""COMPUTED_VALUE"""),"⚪ New") | D20: =IFERROR(__xludf.DUMMYFUNCTION("""COMPUTED_VALUE"""),"r/IndiaProperty") | I20: =IFERROR(__xludf.DUMMYFUNCTION("""COMPUTED_VALUE"""),"https://www.google.com/search?q=https://www.reddit.com/r/IndiaProperty/")
B21: =IFERROR(__xludf.DUMMYFUNCTION("""COMPUTED_VALUE"""),16) | C21: =IFERROR(__xludf.DUMMYFUNCTION("""COMPUTED_VALUE"""),"⚪ New") | D21: =IFERROR(__xludf.DUMMYFUNCTION("""COMPUTED_VALUE"""),"r/IndiaRealEstate") | I21: =IFERROR(__xludf.DUMMYFUNCTION("""COMPUTED_VALUE"""),"https://www.google.com/search?q=https://www.reddit.com/r/IndiaRealEstate/")
B22: =IFERROR(__xludf.DUMMYFUNCTION("""COMPUTED_VALUE"""),17) | C22: =IFERROR(__xludf.DUMMYFUNCTION("""COMPUTED_VALUE"""),"⚪ New") | D22: =IFERROR(__xludf.DUMMYFUNCTION("""COMPUTED_VALUE"""),"r/PassiveIncomeIndia") | I22: =IFERROR(__xludf.DUMMYFUNCTION("""COMPUTED_VALUE"""),"https://www.google.com/search?q=https://www.reddit.com/r/PassiveIncomeIndia/")
B23: =IFERROR(__xludf.DUMMYFUNCTION("""COMPUTED_VALUE"""),18) | C23: =IFERROR(__xludf.DUMMYFUNCTION("""COMPUTED_VALUE"""),"⚪ New") | D23: =IFERROR(__xludf.DUMMYFUNCTION("""COMPUTED_VALUE"""),"r/Finance") | I23: =IFERROR(__xludf.DUMMYFUNCTION("""COMPUTED_VALUE"""),"https://www.reddit.com/r/Finance/")
B24: =IFERROR(__xludf.DUMMYFUNCTION("""COMPUTED_VALUE"""),19) | C24: =IFERROR(__xludf.DUMMYFUNCTION("""COMPUTED_VALUE"""),"⚪ New") | D24: =IFERROR(__xludf.DUMMYFUNCTION("""COMPUTED_VALUE"""),"r/FinancialPlanning") | I24: =IFERROR(__xludf.DUMMYFUNCTION("""COMPUTED_VALUE"""),"https://www.reddit.com/r/FinancialPlanning/")
B25: =IFERROR(__xludf.DUMMYFUNCTION("""COMPUTED_VALUE"""),20) | C25: =IFERROR(__xludf.DUMMYFUNCTION("""COMPUTED_VALUE"""),"⚪ New") | D25: =IFERROR(__xludf.DUMMYFUNCTION("""COMPUTED_VALUE"""),"r/Investing") | I25: =IFERROR(__xludf.DUMMYFUNCTION("""COMPUTED_VALUE"""),"https://www.reddit.com/r/Investing/")
B26: =IFERROR(__xludf.DUMMYFUNCTION("""COMPUTED_VALUE"""),21) | C26: =IFERROR(__xludf.DUMMYFUNCTION("""COMPUTED_VALUE"""),"⚪ New") | D26: =IFERROR(__xludf.DUMMYFUNCTION("""COMPUTED_VALUE"""),"r/Retirement") | I26: =IFERROR(__xludf.DUMMYFUNCTION("""COMPUTED_VALUE"""),"https://www.reddit.com/r/Retirement/")
B27: =IFERROR(__xludf.DUMMYFUNCTION("""COMPUTED_VALUE"""),22) | C27: =IFERROR(__xludf.DUMMYFUNCTION("""COMPUTED_VALUE"""),"⚪ New") | D27: =IFERROR(__xludf.DUMMYFUNCTION("""COMPUTED_VALUE"""),"r/CreditCards") | I27: =IFERROR(__xludf.DUMMYFUNCTION("""COMPUTED_VALUE"""),"https://www.reddit.com/r/CreditCards/")
B28: =IFERROR(__xludf.DUMMYFUNCTION("""COMPUTED_VALUE"""),23) | C28: =IFERROR(__xludf.DUMMYFUNCTION("""COMPUTED_VALUE"""),"⚪ New") | D28: =IFERROR(__xludf.DUMMYFUNCTION("""COMPUTED_VALUE"""),"r/Tax") | I28: =IFERROR(__xludf.DUMMYFUNCTION("""COMPUTED_VALUE"""),"https://www.reddit.com/r/Tax/")
B29: =IFERROR(__xludf.DUMMYFUNCTION("""COMPUTED_VALUE"""),24) | C29: =IFERROR(__xludf.DUMMYFUNCTION("""COMPUTED_VALUE"""),"⚪ New") | D29: =IFERROR(__xludf.DUMMYFUNCTION("""COMPUTED_VALUE"""),"r/Economics") | I29: =IFERROR(__xludf.DUMMYFUNCTION("""COMPUTED_VALUE"""),"https://www.reddit.com/r/Economics/")
B30: =IFERROR(__xludf.DUMMYFUNCTION("""COMPUTED_VALUE"""),25) | C30: =IFERROR(__xludf.DUMMYFUNCTION("""COMPUTED_VALUE"""),"⚪ New") | D30: =IFERROR(__xludf.DUMMYFUNCTION("""COMPUTED_VALUE"""),"r/CryptoCurrency") | I30: =IFERROR(__xludf.DUMMYFUNCTION("""COMPUTED_VALUE"""),"https://www.reddit.com/r/CryptoCurrency/")
B31: =IFERROR(__xludf.DUMMYFUNCTION("""COMPUTED_VALUE"""),26) | C31: =IFERROR(__xludf.DUMMYFUNCTION("""COMPUTED_VALUE"""),"⚪ New") | D31: =IFERROR(__xludf.DUMMYFUNCTION("""COMPUTED_VALUE"""),"r/SecurityAnalysis") | I31: =IFERROR(__xludf.DUMMYFUNCTION("""COMPUTED_VALUE"""),"https://www.reddit.com/r/SecurityAnalysis/")
B32: =IFERROR(__xludf.DUMMYFUNCTION("""COMPUTED_VALUE"""),27) | C32: =IFERROR(__xludf.DUMMYFUNCTION("""COMPUTED_VALUE"""),"⚪ New") | D32: =IFERROR(__xludf.DUMMYFUNCTION("""COMPUTED_VALUE"""),"r/PovertyFinance") | I32: =IFERROR(__xludf.DUMMYFUNCTION("""COMPUTED_VALUE"""),"https://www.reddit.com/r/PovertyFinance/")
B33: =IFERROR(__xludf.DUMMYFUNCTION("""COMPUTED_VALUE"""),28) | C33: =IFERROR(__xludf.DUMMYFUNCTION("""COMPUTED_VALUE"""),"⚪ New") | D33: =IFERROR(__xludf.DUMMYFUNCTION("""COMPUTED_VALUE"""),"r/Frugal") | I33: =IFERROR(__xludf.DUMMYFUNCTION("""COMPUTED_VALUE"""),"https://www.reddit.com/r/Frugal/")
